Workbook
Name OwnerName: Settings!$C$6
Name Age: Settings!$C$7
Name HeightCm: Settings!$C$8
Name StartWeight: Settings!$C$9
Name StartBF: Settings!$C$10
Name GoalBF: Settings!$C$11
Name LeanMass: Settings!$C$12
Name GoalWeight: Settings!$C$13
Name TrackStart: Settings!$C$15
Name WakeTime: Settings!$C$16
Name TrainTime: Settings!$C$17
Name WorkHours: Settings!$C$18
Name LightsOut: Settings!$C$19
Name WorkDays: Settings!$C$20
Name StrDays: Settings!$C$21
Name ProtTarget: Settings!$C$23
Name ProtHit: Settings!$C$24
Name ProtDinner: Settings!$C$25
Name ProtMVD: Settings!$C$26
Name KcalMin: Settings!$C$27
Name KcalMax: Settings!$C$28
Name FatRange: Settings!$C$29
Name WaterHit: Settings!$C$30
Name WaterMVD: Settings!$C$31
Name SleepTarget: Settings!$C$33
Name SleepMin: Settings!$C$34
Name SleepLow: Settings!$C$35
Name Steps1: Settings!$C$37
Name Steps2: Settings!$C$38
Name Steps3: Settings!$C$39
Name StepsAlert: Settings!$C$40
Name LossMin: Settings!$C$42
Name LossMax: Settings!$C$43
Name LossMaxPct: Settings!$C$44
Name Band1: Settings!$C$46
Name Band2: Settings!$C$47
Name Band3: Settings!$C$48
Name RecoveryLow: Settings!$C$49
Name PlanTraining: Settings!$H$7:$H$13
Name PlanRest: Settings!$I$7:$I$13
Name k_Mode: Calc!$B$4
Name k_Wd: Calc!$B$5
Name k_PlanT: Calc!$B$6
Name k_PlanR: Calc!$B$7
Name k_T_wake: Calc!$B$8
Name k_T_pray: Calc!$B$9
Name k_T_mob: Calc!$B$10
Name k_T_move: Calc!$B$11
Name k_T_top3: Calc!$B$12
Name k_T_love: Calc!$B$13
Name k_T_read: Calc!$B$14
Name k_T_shut: Calc!$B$15
Name k_T_sleep: Calc!$B$16
Name k_T_str: Calc!$B$17
Name k_T_prog: Calc!$B$18
Name k_T_core: Calc!$B$19
Name k_T_calf: Calc!$B$20
Name k_T_cardio: Calc!$B$21
Name k_T_deep: Calc!$B$22
Name k_T_brk: Calc!$B$23

Sheet Start Here
B2: LIFE OS · START HERE
B3: Lucas's personal operating system. Consistency > Intensity · Progress > Perfection · Systems > Motivation · Health > Extreme results
B5: THE 60-SECOND DAILY CHECK-IN | E5: THE TABS
B6: 1 | C6: Open this month's tab (Oct 2026, Nov 2026…). Today's date is highlighted in yellow. | E6: Dashboard | F6: Today · this week · this month · coach · system check · pillars · charts. Change the yellow date to look back.
B7: 2 | C7: Tick the habits you did. Level 3 is bonus only. | E7: Week Plan | F7: Top 3 and tasks for each day, daily donuts and check-ins (task-tracker layout).
B8: 3 | C8: Type the numbers you have in BODY & MIND: weight, steps, protein, water, sleep, energy, stress, mood. Blank is fine. | E8: Month tabs | F8: The habit grid, scores, body & mind numbers, charts. This is where you log.
B9: 4 | C9: Hard day? Type M in the Day mode row. Sick? Type S. Planned rest? R. | E9: Body | F9: Profile, goal estimate, measurements every 2 weeks, monthly photos, trend charts.
B10: 5 | C10: Glance at the Dashboard: Foundation score, rolling 7-day, Smart Coach. | E10: Weekly Review | F10: Sunday, 15–30 min. Numbers fill themselves; write wins, problems and ONE change.
E11: Monthly Review | F11: Once a month: body, health, mind, spirit, relationships, business, stop/start/continue.
E12: Habit Library | F12: Every habit with level, pillar, target, what counts, and 7/30-day scores.
E13: Plan & Routines | F13: The playbook: routines, training, nutrition, MVD, sick days, eye and jaw notes.
E14: Settings | F14: Targets and thresholds. Change them here and everything follows.
E15: Calc · Data | F15: The engine. Don't type there.
B17: THREE LEVELS | E17: HOW SCORING WORKS
B18: Level 1 | C18: Non-negotiables. The small daily foundation: morning reset, prayer, mobility, movement, Top 3, fiancée, read/learn, shutdown, lights out (+ protein, water, steps, sleep from your numbers). | E18: Foundation | F18: Each day gets one score from 9 things: sleep, movement, protein, water, steps, prayer, Top 3 (work days only), fiancée, read/learn.
B19: Level 2 | C19: High value, scored against weekly targets: strength 4×, progression, core 3×, calves 3×, cardio 2×, deep work, breaks, home reset, son, couple time, family, church, meal prep. | E19: Rolling | F19: The headline numbers are rolling 7-day and 30-day averages, not streaks. One missed day can't wipe anything out.
B20: Level 3 | C20: Optional. Never counts against you. | E20: Bands | F20: Green ≥ 85% · Good 70–84% · Needs attention 50–69% · Reset < 50%
E21: Modes | F21: M days are scored on the Minimum Viable Day list. S days are paused.
E22: Missed vs failed | F22: The System Check separates 'one off day', 'missed a few habits' and 'the system is too complicated'. It never says 'failed'. When adherence drops, it tells you to simplify, not to try harder.
B24: PRINCIPLES | E24: GOOGLE SHEETS SETUP · once
B25: 1 | C25: Consistency > intensity | E25: 1 | F25: Google Drive → New → File upload → Lucas-Life-OS.xlsx → open it → File → Save as Google Sheets.
B26: 2 | C26: Progress > perfection | E26: 2 | F26: In the Google Sheet: Extensions → Apps Script. Paste the contents of life_os_setup.gs, save, click Run on finishSetup and allow access.
B27: 3 | C27: Systems > motivation | E27: 3 | F27: That converts the grids to real checkboxes, applies Montserrat, dark-styles the charts and adds a 'Life OS' menu (Go to today · New week).
B28: 4 | C28: Health > extreme results | E28: No script? | F28: Everything still works: type x in a cell instead of ticking. Or select a grid and use Insert → Checkbox.
B29: Note | C29: This is a personal planning tool, not medical advice. For eyes, jaw or anything persistent, see a professional.

Sheet Dashboard
B2: LIFE OS | N2: SHOWING | P2: =TODAY()
N3: DAY MODE | P3: =IF(k_Mode="M","Minimum Viable Day",IF(k_Mode="S","Sick day · score paused",IF(k_Mode="R","Rest / recovery day","Normal day")))
B4: Lucas · personal operating system · Consistency > Intensity · Progress > Perfection · Systems > Motivation · Health > Extreme results | N4: type any date in the yellow cell to look back · =TODAY() for live
B6: FOUNDATION · TODAY | E6: ROLLING 7-DAY | H6: ROLLING 30-DAY | K6: STATUS · 7 DAY | N6: WEIGHT · 7-DAY AVG | Q6: WEEKLY RATE
B7: =k_T_score | E7: =k_T_r7 | H7: =k_T_r30 | K7: =k_Status7 | N7: =IF(ISNUMBER(k_T_w7),k_T_w7,"—") | Q7: =IF(ISNUMBER(k_Rate),k_Rate,"—")
B9: =IF(NOT(ISNUMBER(k_T_score)),IF(k_Mode="S","sick day · paused","not logged yet"),k_T_l1done&" of "&k_T_l1app&" non-negotiables") | E9: =k_Status7 | H9: =k_Status30 | K9: ="Green ≥85 · Good 70–84 · Attention 50–69 · Reset <50" | N9: =IF(ISNUMBER(k_T_weight),"today "&TEXT(k_T_weight,"0.0")&" kg","no weigh-in today") | Q9: =k_RateFlag
B11: ="TODAY · "&UPPER(TEXT(AsOf,"dddd"))&" · 06:00 wake + reset · 06:30 "&k_PlanT&" · 10:00–20:00 work · "&k_PlanR&" · 22:00 lights out"
B13: TODAY
B14: BODY | F14: MIND | I14: SPIRIT | L14: LIFE | P14: RECOVERY
B15: Weight | D15: =IF(ISNUMBER(k_T_weight),TEXT(k_T_weight,"0.0")&" kg","—") | F15: Read / learn | H15: =IF(k_T_read=1,"✓ done",IF(k_T_read="","—","○ open")) | I15: Prayer + Word | K15: =IF(k_T_pray=1,"✓ done",IF(k_T_pray="","—","○ open")) | L15: Top 3 set | N15: =IF(k_T_top3=1,"✓ done",IF(k_T_top3="","—","○ open")) | P15: Sleep | R15: =IF(ISNUMBER(k_T_sleeph),TEXT(k_T_sleeph,"0.0")&" h","—")
B16: Steps | D16: =IF(ISNUMBER(k_T_steps),TEXT(k_T_steps,"#,##0")&" / "&TEXT(k_T_stepT,"#,##0"),"— / "&TEXT(k_T_stepT,"#,##0")) | F16: Deep work | H16: =IF(k_T_deep=1,"✓ done",IF(k_T_deep="","—","○ open")) | I16: Church · wk | K16: =IF(k_Church7>0,"✓ "&k_Church7,"○ 0") | L16: Fiancée time | N16: =IF(k_T_love=1,"✓ done",IF(k_T_love="","—","○ open")) | P16: Lights out | R16: =IF(k_T_sleep=1,"✓ done",IF(k_T_sleep="","—","○ open"))
B17: Workout | D17: =IF(k_T_move=1,"✓ done",IF(k_T_move="","—","○ open")) | F17: Med / journal | H17: =IF(k_T_med=1,"✓ done",IF(k_T_med="","—","○ open")) | I17: Prayer · 7d | K17: =k_Pray7&" / 7" | L17: Son · this week | N17: =IF(k_Son7>0,"✓ "&k_Son7,"○ 0") | P17: Energy | R17: =IF(ISNUMBER(k_T_energy),TEXT(k_T_energy,"0")&"/10","—")
B18: Protein | D18: =IF(ISNUMBER(k_T_protein),TEXT(k_T_protein,"0")&" / "&ProtTarget&" g","— / "&ProtTarget&" g") | F18: Mood | H18: =IF(ISNUMBER(k_T_mood),TEXT(k_T_mood,"0")&"/10","—") | L18: Family · this week | N18: =IF(k_Family7>0,"✓ "&k_Family7,"○ 0") | P18: Stress | R18: =IF(ISNUMBER(k_T_stress),TEXT(k_T_stress,"0")&"/10","—")
B19: Water | D19: =IF(ISNUMBER(k_T_water),TEXT(k_T_water,"0.0")&" / "&TEXT(WaterHit,"0.0")&" L","— / "&TEXT(WaterHit,"0.0")&" L") | L19: Home reset | N19: =IF(k_T_home=1,"✓ done",IF(k_T_home="","—","○ open")) | P19: Recovery · 7d | R19: =IF(ISNUMBER(k_Recovery),k_Recovery&" / 100","—")
B20: Calories | D20: =IF(ISNUMBER(k_T_kcal),TEXT(k_T_kcal,"#,##0"),"—") | L20: Shutdown | N20: =IF(k_T_shut=1,"✓ done",IF(k_T_shut="","—","○ open"))
B22: SMART COACH · adaptive recommendations | N22: SYSTEM CHECK
B23: =IF(k_Mode="S","🤒 Sick-day rule: rest, fluids, protein-conscious food, sleep. No hard training, no deficit, no forced cardio. Resume gradually.","✓ Not a sick day.") | N23: =IF(NOT(ISNUMBER(k_T_r7)),"Start logging",IF(k_L1low>=3,"The system is too complicated",IF(k_T_r7<Band3,"Reset week, not a failure",IF(k_T_r7<Band2,"Missed a few habits",IF(AND(ISNUMBER(k_Y_score),k_Y_score<0.5),"One off day","System working")))))
B24: =IF(NOT(ISNUMBER(k_T_sleeph)),"· Log sleep hours to unlock recovery advice.",IF(k_T_sleeph<SleepLow,"⚠ Under "&SleepLow&" h sleep → make today a recovery day: walk + mobility, or cut the session to 2 easy sets per move.","✓ Sleep "&TEXT(k_T_sleeph,"0.0")&" h, train as planned."))
B25: =IF(NOT(ISNUMBER(k_T_protein)),"· Log protein to get a dinner nudge.",IF(k_T_protein<ProtDinner,"⚠ Protein at "&k_T_protein&" g → make dinner high-protein: chicken, eggs, lean beef, dholl + a whey shake (+25 g).","✓ Protein on track ("&k_T_protein&" g)."))
B26: =IF(AND(AsOf=TODAY(),HOUR(NOW())>=18,ISNUMBER(k_T_steps),k_T_steps<StepsAlert),"⚠ Under "&TEXT(StepsAlert,"#,##0")&" steps after 18:00 → 20–30 min walk (with your fiancée or son counts twice).",IF(ISNUMBER(k_T_steps),"✓ Steps "&TEXT(k_T_steps,"#,##0")&" of "&TEXT(k_T_stepT,"#,##0")&" target.","· Steps target today: "&TEXT(k_T_stepT,"#,##0")&".")) | N26: =IF(NOT(ISNUMBER(k_T_r7)),"Tick today's habits on the month tab. The scores appear from the first logged day.",IF(k_L1low>=3,"3+ non-negotiables under 50% this week. That's a design problem, not a character problem. Run Minimum Viable Days for 7 days and drop one high-value habit.",IF(k_T_r7<Band3,"Rolling 7-day under 50%. Don't add motivation tactics. Shrink to the Minimum Viable Day until it's back above 70%.",IF(k_T_r7<Band2,"You missed some habits. That's data, not failure. Pick the one that matters most and protect it tomorrow.",IF(AND(ISNUMBER(k_Y_score),k_Y_score<0.5),"Yesterday was low, the rolling average is still healthy. Restart today. No make-up work, no punishment.","Consistency > intensity. Keep the system the same size; don't add habits just because it's going well.")))))
B27: =IF(AND(k_Y_strday=1,k_Y_active=1,k_Y_mode<>"S",k_Y_str=0),"⚠ Yesterday's session was missed → don't reshuffle the week. Do the 20-minute minimum workout today (Plan & Routines).","✓ Training on plan. Today: "&k_PlanT&".")
B28: =IF(AND(ISNUMBER(k_T_w7),ISNUMBER(k_W7_m14)),IF(k_T_w7>=k_W7_m14,"⚠ 7-day average hasn't dropped in 14 days → trim 150–200 kcal or add ~2,000 steps a day. One change only.","✓ Weight trend moving the right way."),"· The weight rules switch on after 2 weeks of weigh-ins.")
B29: =IF(k_LossTooFast=1,"⚠ Losing more than 1% bodyweight a week, twice in a row → add 150–200 kcal and check recovery. Fat loss, not muscle loss.",IF(ISNUMBER(k_Rate),"✓ Rate of loss is sustainable (target 0.4–0.8 kg/week).","· The pace check starts after 2 weeks of weigh-ins."))
B30: =IF(NOT(ISNUMBER(k_Prot7)),"· Protein average appears after a few logged days.",IF(k_Prot7<ProtHit,"⚠ Protein averaging "&TEXT(k_Prot7,"0")&" g this week → muscle-preservation risk. Add one whey serving or an extra egg/chicken portion.","✓ Protein averaging "&TEXT(k_Prot7,"0")&" g.")) | N30: Non-negotiables · 7d | R30: =k_L1avg7
B31: =IF(NOT(ISNUMBER(k_Sleep7)),"· Sleep average appears after a few logged nights.",IF(k_Sleep7<SleepMin,"⚠ Sleep averaging "&TEXT(k_Sleep7,"0.0")&" h → protect 22:00 lights out before adding anything else.","✓ Sleep averaging "&TEXT(k_Sleep7,"0.0")&" h.")) | N31: High-value vs targets · 7d | R31: =k_L2avg7
B32: =IF(AND(k_Str14>=3,ISNUMBER(k_ProgRate14),k_ProgRate14<0.25),"⚠ Strength is stalling (progress in "&TEXT(k_ProgRate14,"0%")&" of sessions) → check sleep, protein and calories before pushing harder.",IF(ISNUMBER(k_ProgRate14),"✓ Progressive overload: "&TEXT(k_ProgRate14,"0%")&" of sessions improved something.","· Tick Progression achieved after each session to track overload.")) | N32: Non-negotiables under 50% | R32: =k_L1low
B33: =IF(AND(ISNUMBER(k_Recovery),k_Recovery<RecoveryLow),"⚠ Recovery score "&k_Recovery&" → lighter training this week: one set fewer, stop 2–3 reps before failure.",IF(ISNUMBER(k_Recovery),"✓ Recovery score "&k_Recovery&" / 100.","· Recovery score appears once you log sleep, energy and stress.")) | N33: Recovery score · 7d | R33: =IF(ISNUMBER(k_Recovery),k_Recovery,"—")
B34: =IF(k_Cardio7>4,"⚠ "&k_Cardio7&" cardio sessions this week → too much cardio eats into recovery and muscle. Keep it to 2–3.","✓ Cardio "&k_Cardio7&" / 2–3 this week.") | N34: Days logged · 7d | R34: =k_Logged7&" / 7"
B35: =IF(AND(ISNUMBER(k_Energy7),k_Energy7<=4),"⚠ Energy low all week → treat it as a recovery week. If it keeps happening, talk to a doctor.",IF(ISNUMBER(k_Energy7),"✓ Energy "&TEXT(k_Energy7,"0.0")&" / 10 this week.","· Log energy 1–10 to track fatigue.")) | N35: MINIMUM VIABLE DAY · water · 10-min walk · protein as close as possible · 5-min mobility · prayer · 10 min with your fiancée · lights out on time
B36: =IF(k_L1low>=3,"⚠ "&k_L1low&" non-negotiables slipped this week → SIMPLIFY THIS WEEK: run Minimum Viable Days, skip the optional list, add nothing new.","✓ No need to simplify. Keep the system the same size.")
B38: THIS WEEK · last 7 days | K38: THIS MONTH · last 30 days
B39: Weight trend (7-day avg vs last week) | G39: =IF(ISNUMBER(k_Rate),TEXT(k_Rate,"+0.00;-0.00")&" kg · "&k_RateFlag,"—") | K39: Weight change (7-day avg) | P39: =IF(ISNUMBER(k_Change30),TEXT(k_Change30,"+0.0;-0.0")&" kg","—")
B40: Strength sessions | G40: =k_Str7&" / 4" | K40: Waist (latest) | P40: =IF(ISNUMBER(k_Waist),TEXT(k_Waist,"0.0")&" cm"&IF(ISNUMBER(k_WaistPrev)," ("&TEXT(k_Waist-k_WaistPrev,"+0.0;-0.0")&")",""),"measure every 2 weeks")
B41: Progression rate (14 days) | G41: =IF(ISNUMBER(k_ProgRate14),TEXT(k_ProgRate14,"0%"),"—") | K41: Progress photos | P41: =IF(k_Photo30>0,"✓ taken","○ due this month")
B42: Core · calves · cardio | G42: =k_Core7&"/3 · "&k_Calf7&"/3 · "&k_Cardio7&"/2" | K42: Strength sessions | P42: =k_Str30&" (target ~17)"
B43: Protein average | G43: =IF(ISNUMBER(k_Prot7),TEXT(k_Prot7,"0")&" g / "&ProtTarget,"—") | K43: Reading / learning days | P43: =k_Read30&" / 30"
B44: Steps average | G44: =IF(ISNUMBER(k_Steps7),TEXT(k_Steps7,"#,##0")&" / "&TEXT(k_T_stepT,"#,##0"),"—") | K44: Prayer days | P44: =k_Pray30&" / 30"
B45: Sleep average | G45: =IF(ISNUMBER(k_Sleep7),TEXT(k_Sleep7,"0.0")&" h","—") | K45: Goal weight (if muscle kept) | P45: =TEXT(GoalWeight,"0.0")&" kg"
B46: Couple time · son · church · meal prep | G46: =k_Date7&" · "&k_Son7&" · "&k_Church7&" · "&k_Prep7 | K46: Weeks to goal at this pace | P46: =IF(ISNUMBER(k_WeeksToGoal),TEXT(k_WeeksToGoal,"0")&" weeks","needs a downward trend")
B48: PILLARS · 30-day consistency (high-value habits are scored against their weekly targets)
...

Sheet Week Plan
B2: WEEK PLAN | N2: WEEK STARTING | Q2: =TODAY()-WEEKDAY(TODAY(),3)
B3: Plan the week · tick tasks here · check-ins and scores pull from your daily log | N3: type a Monday to plan ahead
B5: DAILY FOUNDATION SCORE | K5: WEEK | N5: CHECK-IN TREND
K14: =IF(ISNUMBER(D64),TEXT(D64,"0%"),"—")
B17: =UPPER(TEXT((WeekStart+0),"dddd")) | E17: =UPPER(TEXT((WeekStart+1),"dddd")) | H17: =UPPER(TEXT((WeekStart+2),"dddd")) | K17: =UPPER(TEXT((WeekStart+3),"dddd")) | N17: =UPPER(TEXT((WeekStart+4),"dddd")) | Q17: =UPPER(TEXT((WeekStart+5),"dddd")) | T17: =UPPER(TEXT((WeekStart+6),"dddd"))
B18: =(WeekStart+0) | E18: =(WeekStart+1) | H18: =(WeekStart+2) | K18: =(WeekStart+3) | N18: =(WeekStart+4) | Q18: =(WeekStart+5) | T18: =(WeekStart+6)
B19: ="06:30 · "&INDEX(PlanTraining,1) | E19: ="06:30 · "&INDEX(PlanTraining,2) | H19: ="06:30 · "&INDEX(PlanTraining,3) | K19: ="06:30 · "&INDEX(PlanTraining,4) | N19: ="06:30 · "&INDEX(PlanTraining,5) | Q19: ="06:30 · "&INDEX(PlanTraining,6) | T19: ="06:30 · "&INDEX(PlanTraining,7)
B28: =IF(ISNUMBER(D57),TEXT(D57,"0%"),"—") | E28: =IF(ISNUMBER(D58),TEXT(D58,"0%"),"—") | H28: =IF(ISNUMBER(D59),TEXT(D59,"0%"),"—") | K28: =IF(ISNUMBER(D60),TEXT(D60,"0%"),"—") | N28: =IF(ISNUMBER(D61),TEXT(D61,"0%"),"—") | Q28: =IF(ISNUMBER(D62),TEXT(D62,"0%"),"—") | T28: =IF(ISNUMBER(D63),TEXT(D63,"0%"),"—")
B29: foundation score | E29: foundation score | H29: foundation score | K29: foundation score | N29: foundation score | Q29: foundation score | T29: foundation score
B30: TOP 3 PRIORITIES | E30: TOP 3 PRIORITIES | H30: TOP 3 PRIORITIES | K30: TOP 3 PRIORITIES | N30: TOP 3 PRIORITIES | Q30: TOP 3 PRIORITIES | T30: TOP 3 PRIORITIES
B34: TASKS | E34: TASKS | H34: TASKS | K34: TASKS | N34: TASKS | Q34: TASKS | T34: TASKS
B43: Completed | C43: =COUNTIF(C31:C42,TRUE)+COUNTIF(C31:C42,"x") | E43: Completed | F43: =COUNTIF(F31:F42,TRUE)+COUNTIF(F31:F42,"x") | H43: Completed | I43: =COUNTIF(I31:I42,TRUE)+COUNTIF(I31:I42,"x") | K43: Completed | L43: =COUNTIF(L31:L42,TRUE)+COUNTIF(L31:L42,"x") | N43: Completed | O43: =COUNTIF(O31:O42,TRUE)+COUNTIF(O31:O42,"x") | Q43: Completed | R43: =COUNTIF(R31:R42,TRUE)+COUNTIF(R31:R42,"x") | T43: Completed | U43: =COUNTIF(U31:U42,TRUE)+COUNTIF(U31:U42,"x")
B44: Not completed | C44: =MAX(0,COUNTA(B31:B33,B35:B42)-(COUNTIF(C31:C42,TRUE)+COUNTIF(C31:C42,"x"))) | E44: Not completed | F44: =MAX(0,COUNTA(E31:E33,E35:E42)-(COUNTIF(F31:F42,TRUE)+COUNTIF(F31:F42,"x"))) | H44: Not completed | I44: =MAX(0,COUNTA(H31:H33,H35:H42)-(COUNTIF(I31:I42,TRUE)+COUNTIF(I31:I42,"x"))) | K44: Not completed | L44: =MAX(0,COUNTA(K31:K33,K35:K42)-(COUNTIF(L31:L42,TRUE)+COUNTIF(L31:L42,"x"))) | N44: Not completed | O44: =MAX(0,COUNTA(N31:N33,N35:N42)-(COUNTIF(O31:O42,TRUE)+COUNTIF(O31:O42,"x"))) | Q44: Not completed | R44: =MAX(0,COUNTA(Q31:Q33,Q35:Q42)-(COUNTIF(R31:R42,TRUE)+COUNTIF(R31:R42,"x"))) | T44: Not completed | U44: =MAX(0,COUNTA(T31:T33,T35:T42)-(COUNTIF(U31:U42,TRUE)+COUNTIF(U31:U42,"x")))
B45: CHECK-IN · from daily log | E45: CHECK-IN · from daily log | H45: CHECK-IN · from daily log | K45: CHECK-IN · from daily log | N45: CHECK-IN · from daily log | Q45: CHECK-IN · from daily log | T45: CHECK-IN · from daily log
B46: ="Sleep "&IF(ISNUMBER(IFERROR(INDEX(Data!$AK$4:$AK$375,MATCH((WeekStart+0),Data!$A$4:$A$375,0)),"")),IF(ISNUMBER((IFERROR(INDEX(Data!$AK$4:$AK$375,MATCH((WeekStart+0),Data!$A$4:$A$375,0)),""))/9),REPT("█",ROUND(MAX(0,MIN(1,(IFERROR(INDEX(Data!$AK$4:$AK$375,MATCH((WeekStart+0),Data!$A$4:$A$375,0)),""))/9))*6,0))&REPT("░",6-ROUND(MAX(0,MIN(1,(IFERROR(INDEX(Data!$AK$4:$AK$375,MATCH((WeekStart+0),Data!$A$4:$A$375,0)),""))/9))*6,0)),""),"") | C46: =IF(ISNUMBER(IFERROR(INDEX(Data!$AK$4:$AK$375,MATCH((WeekStart+0),Data!$A$4:$A$375,0)),"")),IFERROR(INDEX(Data!$AK$4:$AK$375,MATCH((WeekStart+0),Data!$A$4:$A$375,0)),""),"") | E46: ="Sleep "&IF(ISNUMBER(IFERROR(INDEX(Data!$AK$4:$AK$375,MATCH((WeekStart+1),Data!$A$4:$A$375,0)),"")),IF(ISNUMBER((IFERROR(INDEX(Data!$AK$4:$AK$375,MATCH((WeekStart+1),Data!$A$4:$A$375,0)),""))/9),REPT("█",ROUND(MAX(0,MIN(1,(IFERROR(INDEX(Data!$AK$4:$AK$375,MATCH((WeekStart+1),Data!$A$4:$A$375,0)),""))/9))*6,0))&REPT("░",6-ROUND(MAX(0,MIN(1,(IFERROR(INDEX(Data!$AK$4:$AK$375,MATCH((WeekStart+1),Data!$A$4:$A$375,0)),""))/9))*6,0)),""),"") | F46: =IF(ISNUMBER(IFERROR(INDEX(Data!$AK$4:$AK$375,MATCH((WeekStart+1),Data!$A$4:$A$375,0)),"")),IFERROR(INDEX(Data!$AK$4:$AK$375,MATCH((WeekStart+1),Data!$A$4:$A$375,0)),""),"") | H46: ="Sleep "&IF(ISNUMBER(IFERROR(INDEX(Data!$AK$4:$AK$375,MATCH((WeekStart+2),Data!$A$4:$A$375,0)),"")),IF(ISNUMBER((IFERROR(INDEX(Data!$AK$4:$AK$375,MATCH((WeekStart+2),Data!$A$4:$A$375,0)),""))/9),REPT("█",ROUND(MAX(0,MIN(1,(IFERROR(INDEX(Data!$AK$4:$AK$375,MATCH((WeekStart+2),Data!$A$4:$A$375,0)),""))/9))*6,0))&REPT("░",6-ROUND(MAX(0,MIN(1,(IFERROR(INDEX(Data!$AK$4:$AK$375,MATCH((WeekStart+2),Data!$A$4:$A$375,0)),""))/9))*6,0)),""),"") | I46: =IF(ISNUMBER(IFERROR(INDEX(Data!$AK$4:$AK$375,MATCH((WeekStart+2),Data!$A$4:$A$375,0)),"")),IFERROR(INDEX(Data!$AK$4:$AK$375,MATCH((WeekStart+2),Data!$A$4:$A$375,0)),""),"") | K46: ="Sleep "&IF(ISNUMBER(IFERROR(INDEX(Data!$AK$4:$AK$375,MATCH((WeekStart+3),Data!$A$4:$A$375,0)),"")),IF(ISNUMBER((IFERROR(INDEX(Data!$AK$4:$AK$375,MATCH((WeekStart+3),Data!$A$4:$A$375,0)),""))/9),REPT("█",ROUND(MAX(0,MIN(1,(IFERROR(INDEX(Data!$AK$4:$AK$375,MATCH((WeekStart+3),Data!$A$4:$A$375,0)),""))/9))*6,0))&REPT("░",6-ROUND(MAX(0,MIN(1,(IFERROR(INDEX(Data!$AK$4:$AK$375,MATCH((WeekStart+3),Data!$A$4:$A$375,0)),""))/9))*6,0)),""),"") | L46: =IF(ISNUMBER(IFERROR(INDEX(Data!$AK$4:$AK$375,MATCH((WeekStart+3),Data!$A$4:$A$375,0)),"")),IFERROR(INDEX(Data!$AK$4:$AK$375,MATCH((WeekStart+3),Data!$A$4:$A$375,0)),""),"") | N46: ="Sleep "&IF(ISNUMBER(IFERROR(INDEX(Data!$AK$4:$AK$375,MATCH((WeekStart+4),Data!$A$4:$A$375,0)),"")),IF(ISNUMBER((IFERROR(INDEX(Data!$AK$4:$AK$375,MATCH((WeekStart+4),Data!$A$4:$A$375,0)),""))/9),REPT("█",ROUND(MAX(0,MIN(1,(IFERROR(INDEX(Data!$AK$4:$AK$375,MATCH((WeekStart+4),Data!$A$4:$A$375,0)),""))/9))*6,0))&REPT("░",6-ROUND(MAX(0,MIN(1,(IFERROR(INDEX(Data!$AK$4:$AK$375,MATCH((WeekStart+4),Data!$A$4:$A$375,0)),""))/9))*6,0)),""),"") | O46: =IF(ISNUMBER(IFERROR(INDEX(Data!$AK$4:$AK$375,MATCH((WeekStart+4),Data!$A$4:$A$375,0)),"")),IFERROR(INDEX(Data!$AK$4:$AK$375,MATCH((WeekStart+4),Data!$A$4:$A$375,0)),""),"") | Q46: ="Sleep "&IF(ISNUMBER(IFERROR(INDEX(Data!$AK$4:$AK$375,MATCH((WeekStart+5),Data!$A$4:$A$375,0)),"")),IF(ISNUMBER((IFERROR(INDEX(Data!$AK$4:$AK$375,MATCH((WeekStart+5),Data!$A$4:$A$375,0)),""))/9),REPT("█",ROUND(MAX(0,MIN(1,(IFERROR(INDEX(Data!$AK$4:$AK$375,MATCH((WeekStart+5),Data!$A$4:$A$375,0)),""))/9))*6,0))&REPT("░",6-ROUND(MAX(0,MIN(1,(IFERROR(INDEX(Data!$AK$4:$AK$375,MATCH((WeekStart+5),Data!$A$4:$A$375,0)),""))/9))*6,0)),""),"") | R46: =IF(ISNUMBER(IFERROR(INDEX(Data!$AK$4:$AK$375,MATCH((WeekStart+5),Data!$A$4:$A$375,0)),"")),IFERROR(INDEX(Data!$AK$4:$AK$375,MATCH((WeekStart+5),Data!$A$4:$A$375,0)),""),"") | T46: ="Sleep "&IF(ISNUMBER(IFERROR(INDEX(Data!$AK$4:$AK$375,MATCH((WeekStart+6),Data!$A$4:$A$375,0)),"")),IF(ISNUMBER((IFERROR(INDEX(Data!$AK$4:$AK$375,MATCH((WeekStart+6),Data!$A$4:$A$375,0)),""))/9),REPT("█",ROUND(MAX(0,MIN(1,(IFERROR(INDEX(Data!$AK$4:$AK$375,MATCH((WeekStart+6),Data!$A$4:$A$375,0)),""))/9))*6,0))&REPT("░",6-ROUND(MAX(0,MIN(1,(IFERROR(INDEX(Data!$AK$4:$AK$375,MATCH((WeekStart+6),Data!$A$4:$A$375,0)),""))/9))*6,0)),""),"") | U46: =IF(ISNUMBER(IFERROR(INDEX(Data!$AK$4:$AK$375,MATCH((WeekStart+6),Data!$A$4:$A$375,0)),"")),IFERROR(INDEX(Data!$AK$4:$AK$375,MATCH((WeekStart+6),Data!$A$4:$A$375,0)),""),"")
B47: ="Energy "&IF(ISNUMBER(IFERROR(INDEX(Data!$AL$4:$AL$375,MATCH((WeekStart+0),Data!$A$4:$A$375,0)),"")),IF(ISNUMBER((IFERROR(INDEX(Data!$AL$4:$AL$375,MATCH((WeekStart+0),Data!$A$4:$A$375,0)),""))/10),REPT("█",ROUND(MAX(0,MIN(1,(IFERROR(INDEX(Data!$AL$4:$AL$375,MATCH((WeekStart+0),Data!$A$4:$A$375,0)),""))/10))*6,0))&REPT("░",6-ROUND(MAX(0,MIN(1,(IFERROR(INDEX(Data!$AL$4:$AL$375,MATCH((WeekStart+0),Data!$A$4:$A$375,0)),""))/10))*6,0)),""),"") | C47: =IF(ISNUMBER(IFERROR(INDEX(Data!$AL$4:$AL$375,MATCH((WeekStart+0),Data!$A$4:$A$375,0)),"")),IFERROR(INDEX(Data!$AL$4:$AL$375,MATCH((WeekStart+0),Data!$A$4:$A$375,0)),""),"") | E47: ="Energy "&IF(ISNUMBER(IFERROR(INDEX(Data!$AL$4:$AL$375,MATCH((WeekStart+1),Data!$A$4:$A$375,0)),"")),IF(ISNUMBER((IFERROR(INDEX(Data!$AL$4:$AL$375,MATCH((WeekStart+1),Data!$A$4:$A$375,0)),""))/10),REPT("█",ROUND(MAX(0,MIN(1,(IFERROR(INDEX(Data!$AL$4:$AL$375,MATCH((WeekStart+1),Data!$A$4:$A$375,0)),""))/10))*6,0))&REPT("░",6-ROUND(MAX(0,MIN(1,(IFERROR(INDEX(Data!$AL$4:$AL$375,MATCH((WeekStart+1),Data!$A$4:$A$375,0)),""))/10))*6,0)),""),"") | F47: =IF(ISNUMBER(IFERROR(INDEX(Data!$AL$4:$AL$375,MATCH((WeekStart+1),Data!$A$4:$A$375,0)),"")),IFERROR(INDEX(Data!$AL$4:$AL$375,MATCH((WeekStart+1),Data!$A$4:$A$375,0)),""),"") | H47: ="Energy "&IF(ISNUMBER(IFERROR(INDEX(Data!$AL$4:$AL$375,MATCH((WeekStart+2),Data!$A$4:$A$375,0)),"")),IF(ISNUMBER((IFERROR(INDEX(Data!$AL$4:$AL$375,MATCH((WeekStart+2),Data!$A$4:$A$375,0)),""))/10),REPT("█",ROUND(MAX(0,MIN(1,(IFERROR(INDEX(Data!$AL$4:$AL$375,MATCH((WeekStart+2),Data!$A$4:$A$375,0)),""))/10))*6,0))&REPT("░",6-ROUND(MAX(0,MIN(1,(IFERROR(INDEX(Data!$AL$4:$AL$375,MATCH((WeekStart+2),Data!$A$4:$A$375,0)),""))/10))*6,0)),""),"") | I47: =IF(ISNUMBER(IFERROR(INDEX(Data!$AL$4:$AL$375,MATCH((WeekStart+2),Data!$A$4:$A$375,0)),"")),IFERROR(INDEX(Data!$AL$4:$AL$375,MATCH((WeekStart+2),Data!$A$4:$A$375,0)),""),"") | K47: ="Energy "&IF(ISNUMBER(IFERROR(INDEX(Data!$AL$4:$AL$375,MATCH((WeekStart+3),Data!$A$4:$A$375,0)),"")),IF(ISNUMBER((IFERROR(INDEX(Data!$AL$4:$AL$375,MATCH((WeekStart+3),Data!$A$4:$A$375,0)),""))/10),REPT("█",ROUND(MAX(0,MIN(1,(IFERROR(INDEX(Data!$AL$4:$AL$375,MATCH((WeekStart+3),Data!$A$4:$A$375,0)),""))/10))*6,0))&REPT("░",6-ROUND(MAX(0,MIN(1,(IFERROR(INDEX(Data!$AL$4:$AL$375,MATCH((WeekStart+3),Data!$A$4:$A$375,0)),""))/10))*6,0)),""),"") | L47: =IF(ISNUMBER(IFERROR(INDEX(Data!$AL$4:$AL$375,MATCH((WeekStart+3),Data!$A$4:$A$375,0)),"")),IFERROR(INDEX(Data!$AL$4:$AL$375,MATCH((WeekStart+3),Data!$A$4:$A$375,0)),""),"") | N47: ="Energy "&IF(ISNUMBER(IFERROR(INDEX(Data!$AL$4:$AL$375,MATCH((WeekStart+4),Data!$A$4:$A$375,0)),"")),IF(ISNUMBER((IFERROR(INDEX(Data!$AL$4:$AL$375,MATCH((WeekStart+4),Data!$A$4:$A$375,0)),""))/10),REPT("█",ROUND(MAX(0,MIN(1,(IFERROR(INDEX(Data!$AL$4:$AL$375,MATCH((WeekStart+4),Data!$A$4:$A$375,0)),""))/10))*6,0))&REPT("░",6-ROUND(MAX(0,MIN(1,(IFERROR(INDEX(Data!$AL$4:$AL$375,MATCH((WeekStart+4),Data!$A$4:$A$375,0)),""))/10))*6,0)),""),"") | O47: =IF(ISNUMBER(IFERROR(INDEX(Data!$AL$4:$AL$375,MATCH((WeekStart+4),Data!$A$4:$A$375,0)),"")),IFERROR(INDEX(Data!$AL$4:$AL$375,MATCH((WeekStart+4),Data!$A$4:$A$375,0)),""),"") | Q47: ="Energy "&IF(ISNUMBER(IFERROR(INDEX(Data!$AL$4:$AL$375,MATCH((WeekStart+5),Data!$A$4:$A$375,0)),"")),IF(ISNUMBER((IFERROR(INDEX(Data!$AL$4:$AL$375,MATCH((WeekStart+5),Data!$A$4:$A$375,0)),""))/10),REPT("█",ROUND(MAX(0,MIN(1,(IFERROR(INDEX(Data!$AL$4:$AL$375,MATCH((WeekStart+5),Data!$A$4:$A$375,0)),""))/10))*6,0))&REPT("░",6-ROUND(MAX(0,MIN(1,(IFERROR(INDEX(Data!$AL$4:$AL$375,MATCH((WeekStart+5),Data!$A$4:$A$375,0)),""))/10))*6,0)),""),"") | R47: =IF(ISNUMBER(IFERROR(INDEX(Data!$AL$4:$AL$375,MATCH((WeekStart+5),Data!$A$4:$A$375,0)),"")),IFERROR(INDEX(Data!$AL$4:$AL$375,MATCH((WeekStart+5),Data!$A$4:$A$375,0)),""),"") | T47: ="Energy "&IF(ISNUMBER(IFERROR(INDEX(Data!$AL$4:$AL$375,MATCH((WeekStart+6),Data!$A$4:$A$375,0)),"")),IF(ISNUMBER((IFERROR(INDEX(Data!$AL$4:$AL$375,MATCH((WeekStart+6),Data!$A$4:$A$375,0)),""))/10),REPT("█",ROUND(MAX(0,MIN(1,(IFERROR(INDEX(Data!$AL$4:$AL$375,MATCH((WeekStart+6),Data!$A$4:$A$375,0)),""))/10))*6,0))&REPT("░",6-ROUND(MAX(0,MIN(1,(IFERROR(INDEX(Data!$AL$4:$AL$375,MATCH((WeekStart+6),Data!$A$4:$A$375,0)),""))/10))*6,0)),""),"") | U47: =IF(ISNUMBER(IFERROR(INDEX(Data!$AL$4:$AL$375,MATCH((WeekStart+6),Data!$A$4:$A$375,0)),"")),IFERROR(INDEX(Data!$AL$4:$AL$375,MATCH((WeekStart+6),Data!$A$4:$A$375,0)),""),"")
B48: ="Stress "&IF(ISNUMBER(IFERROR(INDEX(Data!$AM$4:$AM$375,MATCH((WeekStart+0),Data!$A$4:$A$375,0)),"")),IF(ISNUMBER((IFERROR(INDEX(Data!$AM$4:$AM$375,MATCH((WeekStart+0),Data!$A$4:$A$375,0)),""))/10),REPT("█",ROUND(MAX(0,MIN(1,(IFERROR(INDEX(Data!$AM$4:$AM$375,MATCH((WeekStart+0),Data!$A$4:$A$375,0)),""))/10))*6,0))&REPT("░",6-ROUND(MAX(0,MIN(1,(IFERROR(INDEX(Data!$AM$4:$AM$375,MATCH((WeekStart+0),Data!$A$4:$A$375,0)),""))/10))*6,0)),""),"") | C48: =IF(ISNUMBER(IFERROR(INDEX(Data!$AM$4:$AM$375,MATCH((WeekStart+0),Data!$A$4:$A$375,0)),"")),IFERROR(INDEX(Data!$AM$4:$AM$375,MATCH((WeekStart+0),Data!$A$4:$A$375,0)),""),"") | E48: ="Stress "&IF(ISNUMBER(IFERROR(INDEX(Data!$AM$4:$AM$375,MATCH((WeekStart+1),Data!$A$4:$A$375,0)),"")),IF(ISNUMBER((IFERROR(INDEX(Data!$AM$4:$AM$375,MATCH((WeekStart+1),Data!$A$4:$A$375,0)),""))/10),REPT("█",ROUND(MAX(0,MIN(1,(IFERROR(INDEX(Data!$AM$4:$AM$375,MATCH((WeekStart+1),Data!$A$4:$A$375,0)),""))/10))*6,0))&REPT("░",6-ROUND(MAX(0,MIN(1,(IFERROR(INDEX(Data!$AM$4:$AM$375,MATCH((WeekStart+1),Data!$A$4:$A$375,0)),""))/10))*6,0)),""),"") | F48: =IF(ISNUMBER(IFERROR(INDEX(Data!$AM$4:$AM$375,MATCH((WeekStart+1),Data!$A$4:$A$375,0)),"")),IFERROR(INDEX(Data!$AM$4:$AM$375,MATCH((WeekStart+1),Data!$A$4:$A$375,0)),""),"") | H48: ="Stress "&IF(ISNUMBER(IFERROR(INDEX(Data!$AM$4:$AM$375,MATCH((WeekStart+2),Data!$A$4:$A$375,0)),"")),IF(ISNUMBER((IFERROR(INDEX(Data!$AM$4:$AM$375,MATCH((WeekStart+2),Data!$A$4:$A$375,0)),""))/10),REPT("█",ROUND(MAX(0,MIN(1,(IFERROR(INDEX(Data!$AM$4:$AM$375,MATCH((WeekStart+2),Data!$A$4:$A$375,0)),""))/10))*6,0))&REPT("░",6-ROUND(MAX(0,MIN(1,(IFERROR(INDEX(Data!$AM$4:$AM$375,MATCH((WeekStart+2),Data!$A$4:$A$375,0)),""))/10))*6,0)),""),"") | I48: =IF(ISNUMBER(IFERROR(INDEX(Data!$AM$4:$AM$375,MATCH((WeekStart+2),Data!$A$4:$A$375,0)),"")),IFERROR(INDEX(Data!$AM$4:$AM$375,MATCH((WeekStart+2),Data!$A$4:$A$375,0)),""),"") | K48: ="Stress "&IF(ISNUMBER(IFERROR(INDEX(Data!$AM$4:$AM$375,MATCH((WeekStart+3),Data!$A$4:$A$375,0)),"")),IF(ISNUMBER((IFERROR(INDEX(Data!$AM$4:$AM$375,MATCH((WeekStart+3),Data!$A$4:$A$375,0)),""))/10),REPT("█",ROUND(MAX(0,MIN(1,(IFERROR(INDEX(Data!$AM$4:$AM$375,MATCH((WeekStart+3),Data!$A$4:$A$375,0)),""))/10))*6,0))&REPT("░",6-ROUND(MAX(0,MIN(1,(IFERROR(INDEX(Data!$AM$4:$AM$375,MATCH((WeekStart+3),Data!$A$4:$A$375,0)),""))/10))*6,0)),""),"") | L48: =IF(ISNUMBER(IFERROR(INDEX(Data!$AM$4:$AM$375,MATCH((WeekStart+3),Data!$A$4:$A$375,0)),"")),IFERROR(INDEX(Data!$AM$4:$AM$375,MATCH((WeekStart+3),Data!$A$4:$A$375,0)),""),"") | N48: ="Stress "&IF(ISNUMBER(IFERROR(INDEX(Data!$AM$4:$AM$375,MATCH((WeekStart+4),Data!$A$4:$A$375,0)),"")),IF(ISNUMBER((IFERROR(INDEX(Data!$AM$4:$AM$375,MATCH((WeekStart+4),Data!$A$4:$A$375,0)),""))/10),REPT("█",ROUND(MAX(0,MIN(1,(IFERROR(INDEX(Data!$AM$4:$AM$375,MATCH((WeekStart+4),Data!$A$4:$A$375,0)),""))/10))*6,0))&REPT("░",6-ROUND(MAX(0,MIN(1,(IFERROR(INDEX(Data!$AM$4:$AM$375,MATCH((WeekStart+4),Data!$A$4:$A$375,0)),""))/10))*6,0)),""),"") | O48: =IF(ISNUMBER(IFERROR(INDEX(Data!$AM$4:$AM$375,MATCH((WeekStart+4),Data!$A$4:$A$375,0)),"")),IFERROR(INDEX(Data!$AM$4:$AM$375,MATCH((WeekStart+4),Data!$A$4:$A$375,0)),""),"") | Q48: ="Stress "&IF(ISNUMBER(IFERROR(INDEX(Data!$AM$4:$AM$375,MATCH((WeekStart+5),Data!$A$4:$A$375,0)),"")),IF(ISNUMBER((IFERROR(INDEX(Data!$AM$4:$AM$375,MATCH((WeekStart+5),Data!$A$4:$A$375,0)),""))/10),REPT("█",ROUND(MAX(0,MIN(1,(IFERROR(INDEX(Data!$AM$4:$AM$375,MATCH((WeekStart+5),Data!$A$4:$A$375,0)),""))/10))*6,0))&REPT("░",6-ROUND(MAX(0,MIN(1,(IFERROR(INDEX(Data!$AM$4:$AM$375,MATCH((WeekStart+5),Data!$A$4:$A$375,0)),""))/10))*6,0)),""),"") | R48: =IF(ISNUMBER(IFERROR(INDEX(Data!$AM$4:$AM$375,MATCH((WeekStart+5),Data!$A$4:$A$375,0)),"")),IFERROR(INDEX(Data!$AM$4:$AM$375,MATCH((WeekStart+5),Data!$A$4:$A$375,0)),""),"") | T48: ="Stress "&IF(ISNUMBER(IFERROR(INDEX(Data!$AM$4:$AM$375,MATCH((WeekStart+6),Data!$A$4:$A$375,0)),"")),IF(ISNUMBER((IFERROR(INDEX(Data!$AM$4:$AM$375,MATCH((WeekStart+6),Data!$A$4:$A$375,0)),""))/10),REPT("█",ROUND(MAX(0,MIN(1,(IFERROR(INDEX(Data!$AM$4:$AM$375,MATCH((WeekStart+6),Data!$A$4:$A$375,0)),""))/10))*6,0))&REPT("░",6-ROUND(MAX(0,MIN(1,(IFERROR(INDEX(Data!$AM$4:$AM$375,MATCH((WeekStart+6),Data!$A$4:$A$375,0)),""))/10))*6,0)),""),"") | U48: =IF(ISNUMBER(IFERROR(INDEX(Data!$AM$4:$AM$375,MATCH((WeekStart+6),Data!$A$4:$A$375,0)),"")),IFERROR(INDEX(Data!$AM$4:$AM$375,MATCH((WeekStart+6),Data!$A$4:$A$375,0)),""),"")
B49: ="Mood "&IF(ISNUMBER(IFERROR(INDEX(Data!$AN$4:$AN$375,MATCH((WeekStart+0),Data!$A$4:$A$375,0)),"")),IF(ISNUMBER((IFERROR(INDEX(Data!$AN$4:$AN$375,MATCH((WeekStart+0),Data!$A$4:$A$375,0)),""))/10),REPT("█",ROUND(MAX(0,MIN(1,(IFERROR(INDEX(Data!$AN$4:$AN$375,MATCH((WeekStart+0),Data!$A$4:$A$375,0)),""))/10))*6,0))&REPT("░",6-ROUND(MAX(0,MIN(1,(IFERROR(INDEX(Data!$AN$4:$AN$375,MATCH((WeekStart+0),Data!$A$4:$A$375,0)),""))/10))*6,0)),""),"") | C49: =IF(ISNUMBER(IFERROR(INDEX(Data!$AN$4:$AN$375,MATCH((WeekStart+0),Data!$A$4:$A$375,0)),"")),IFERROR(INDEX(Data!$AN$4:$AN$375,MATCH((WeekStart+0),Data!$A$4:$A$375,0)),""),"") | E49: ="Mood "&IF(ISNUMBER(IFERROR(INDEX(Data!$AN$4:$AN$375,MATCH((WeekStart+1),Data!$A$4:$A$375,0)),"")),IF(ISNUMBER((IFERROR(INDEX(Data!$AN$4:$AN$375,MATCH((WeekStart+1),Data!$A$4:$A$375,0)),""))/10),REPT("█",ROUND(MAX(0,MIN(1,(IFERROR(INDEX(Data!$AN$4:$AN$375,MATCH((WeekStart+1),Data!$A$4:$A$375,0)),""))/10))*6,0))&REPT("░",6-ROUND(MAX(0,MIN(1,(IFERROR(INDEX(Data!$AN$4:$AN$375,MATCH((WeekStart+1),Data!$A$4:$A$375,0)),""))/10))*6,0)),""),"") | F49: =IF(ISNUMBER(IFERROR(INDEX(Data!$AN$4:$AN$375,MATCH((WeekStart+1),Data!$A$4:$A$375,0)),"")),IFERROR(INDEX(Data!$AN$4:$AN$375,MATCH((WeekStart+1),Data!$A$4:$A$375,0)),""),"") | H49: ="Mood "&IF(ISNUMBER(IFERROR(INDEX(Data!$AN$4:$AN$375,MATCH((WeekStart+2),Data!$A$4:$A$375,0)),"")),IF(ISNUMBER((IFERROR(INDEX(Data!$AN$4:$AN$375,MATCH((WeekStart+2),Data!$A$4:$A$375,0)),""))/10),REPT("█",ROUND(MAX(0,MIN(1,(IFERROR(INDEX(Data!$AN$4:$AN$375,MATCH((WeekStart+2),Data!$A$4:$A$375,0)),""))/10))*6,0))&REPT("░",6-ROUND(MAX(0,MIN(1,(IFERROR(INDEX(Data!$AN$4:$AN$375,MATCH((WeekStart+2),Data!$A$4:$A$375,0)),""))/10))*6,0)),""),"") | I49: =IF(ISNUMBER(IFERROR(INDEX(Data!$AN$4:$AN$375,MATCH((WeekStart+2),Data!$A$4:$A$375,0)),"")),IFERROR(INDEX(Data!$AN$4:$AN$375,MATCH((WeekStart+2),Data!$A$4:$A$375,0)),""),"") | K49: ="Mood "&IF(ISNUMBER(IFERROR(INDEX(Data!$AN$4:$AN$375,MATCH((WeekStart+3),Data!$A$4:$A$375,0)),"")),IF(ISNUMBER((IFERROR(INDEX(Data!$AN$4:$AN$375,MATCH((WeekStart+3),Data!$A$4:$A$375,0)),""))/10),REPT("█",ROUND(MAX(0,MIN(1,(IFERROR(INDEX(Data!$AN$4:$AN$375,MATCH((WeekStart+3),Data!$A$4:$A$375,0)),""))/10))*6,0))&REPT("░",6-ROUND(MAX(0,MIN(1,(IFERROR(INDEX(Data!$AN$4:$AN$375,MATCH((WeekStart+3),Data!$A$4:$A$375,0)),""))/10))*6,0)),""),"") | L49: =IF(ISNUMBER(IFERROR(INDEX(Data!$AN$4:$AN$375,MATCH((WeekStart+3),Data!$A$4:$A$375,0)),"")),IFERROR(INDEX(Data!$AN$4:$AN$375,MATCH((WeekStart+3),Data!$A$4:$A$375,0)),""),"") | N49: ="Mood "&IF(ISNUMBER(IFERROR(INDEX(Data!$AN$4:$AN$375,MATCH((WeekStart+4),Data!$A$4:$A$375,0)),"")),IF(ISNUMBER((IFERROR(INDEX(Data!$AN$4:$AN$375,MATCH((WeekStart+4),Data!$A$4:$A$375,0)),""))/10),REPT("█",ROUND(MAX(0,MIN(1,(IFERROR(INDEX(Data!$AN$4:$AN$375,MATCH((WeekStart+4),Data!$A$4:$A$375,0)),""))/10))*6,0))&REPT("░",6-ROUND(MAX(0,MIN(1,(IFERROR(INDEX(Data!$AN$4:$AN$375,MATCH((WeekStart+4),Data!$A$4:$A$375,0)),""))/10))*6,0)),""),"") | O49: =IF(ISNUMBER(IFERROR(INDEX(Data!$AN$4:$AN$375,MATCH((WeekStart+4),Data!$A$4:$A$375,0)),"")),IFERROR(INDEX(Data!$AN$4:$AN$375,MATCH((WeekStart+4),Data!$A$4:$A$375,0)),""),"") | Q49: ="Mood "&IF(ISNUMBER(IFERROR(INDEX(Data!$AN$4:$AN$375,MATCH((WeekStart+5),Data!$A$4:$A$375,0)),"")),IF(ISNUMBER((IFERROR(INDEX(Data!$AN$4:$AN$375,MATCH((WeekStart+5),Data!$A$4:$A$375,0)),""))/10),REPT("█",ROUND(MAX(0,MIN(1,(IFERROR(INDEX(Data!$AN$4:$AN$375,MATCH((WeekStart+5),Data!$A$4:$A$375,0)),""))/10))*6,0))&REPT("░",6-ROUND(MAX(0,MIN(1,(IFERROR(INDEX(Data!$AN$4:$AN$375,MATCH((WeekStart+5),Data!$A$4:$A$375,0)),""))/10))*6,0)),""),"") | R49: =IF(ISNUMBER(IFERROR(INDEX(Data!$AN$4:$AN$375,MATCH((WeekStart+5),Data!$A$4:$A$375,0)),"")),IFERROR(INDEX(Data!$AN$4:$AN$375,MATCH((WeekStart+5),Data!$A$4:$A$375,0)),""),"") | T49: ="Mood "&IF(ISNUMBER(IFERROR(INDEX(Data!$AN$4:$AN$375,MATCH((WeekStart+6),Data!$A$4:$A$375,0)),"")),IF(ISNUMBER((IFERROR(INDEX(Data!$AN$4:$AN$375,MATCH((WeekStart+6),Data!$A$4:$A$375,0)),""))/10),REPT("█",ROUND(MAX(0,MIN(1,(IFERROR(INDEX(Data!$AN$4:$AN$375,MATCH((WeekStart+6),Data!$A$4:$A$375,0)),""))/10))*6,0))&REPT("░",6-ROUND(MAX(0,MIN(1,(IFERROR(INDEX(Data!$AN$4:$AN$375,MATCH((WeekStart+6),Data!$A$4:$A$375,0)),""))/10))*6,0)),""),"") | U49: =IF(ISNUMBER(IFERROR(INDEX(Data!$AN$4:$AN$375,MATCH((WeekStart+6),Data!$A$4:$A$375,0)),"")),IFERROR(INDEX(Data!$AN$4:$AN$375,MATCH((WeekStart+6),Data!$A$4:$A$375,0)),""),"")
B50: ="Protein "&IF(ISNUMBER(IFERROR(INDEX(Data!$AH$4:$AH$375,MATCH((WeekStart+0),Data!$A$4:$A$375,0)),"")),IF(ISNUMBER((IFERROR(INDEX(Data!$AH$4:$AH$375,MATCH((WeekStart+0),Data!$A$4:$A$375,0)),""))/150),REPT("█",ROUND(MAX(0,MIN(1,(IFERROR(INDEX(Data!$AH$4:$AH$375,MATCH((WeekStart+0),Data!$A$4:$A$375,0)),""))/150))*6,0))&REPT("░",6-ROUND(MAX(0,MIN(1,(IFERROR(INDEX(Data!$AH$4:$AH$375,MATCH((WeekStart+0),Data!$A$4:$A$375,0)),""))/150))*6,0)),""),"") | C50: =IF(ISNUMBER(IFERROR(INDEX(Data!$AH$4:$AH$375,MATCH((WeekStart+0),Data!$A$4:$A$375,0)),"")),IFERROR(INDEX(Data!$AH$4:$AH$375,MATCH((WeekStart+0),Data!$A$4:$A$375,0)),""),"") | E50: ="Protein "&IF(ISNUMBER(IFERROR(INDEX(Data!$AH$4:$AH$375,MATCH((WeekStart+1),Data!$A$4:$A$375,0)),"")),IF(ISNUMBER((IFERROR(INDEX(Data!$AH$4:$AH$375,MATCH((WeekStart+1),Data!$A$4:$A$375,0)),""))/150),REPT("█",ROUND(MAX(0,MIN(1,(IFERROR(INDEX(Data!$AH$4:$AH$375,MATCH((WeekStart+1),Data!$A$4:$A$375,0)),""))/150))*6,0))&REPT("░",6-ROUND(MAX(0,MIN(1,(IFERROR(INDEX(Data!$AH$4:$AH$375,MATCH((WeekStart+1),Data!$A$4:$A$375,0)),""))/150))*6,0)),""),"") | F50: =IF(ISNUMBER(IFERROR(INDEX(Data!$AH$4:$AH$375,MATCH((WeekStart+1),Data!$A$4:$A$375,0)),"")),IFERROR(INDEX(Data!$AH$4:$AH$375,MATCH((WeekStart+1),Data!$A$4:$A$375,0)),""),"") | H50: ="Protein "&IF(ISNUMBER(IFERROR(INDEX(Data!$AH$4:$AH$375,MATCH((WeekStart+2),Data!$A$4:$A$375,0)),"")),IF(ISNUMBER((IFERROR(INDEX(Data!$AH$4:$AH$375,MATCH((WeekStart+2),Data!$A$4:$A$375,0)),""))/150),REPT("█",ROUND(MAX(0,MIN(1,(IFERROR(INDEX(Data!$AH$4:$AH$375,MATCH((WeekStart+2),Data!$A$4:$A$375,0)),""))/150))*6,0))&REPT("░",6-ROUND(MAX(0,MIN(1,(IFERROR(INDEX(Data!$AH$4:$AH$375,MATCH((WeekStart+2),Data!$A$4:$A$375,0)),""))/150))*6,0)),""),"") | I50: =IF(ISNUMBER(IFERROR(INDEX(Data!$AH$4:$AH$375,MATCH((WeekStart+2),Data!$A$4:$A$375,0)),"")),IFERROR(INDEX(Data!$AH$4:$AH$375,MATCH((WeekStart+2),Data!$A$4:$A$375,0)),""),"") | K50: ="Protein "&IF(ISNUMBER(IFERROR(INDEX(Data!$AH$4:$AH$375,MATCH((WeekStart+3),Data!$A$4:$A$375,0)),"")),IF(ISNUMBER((IFERROR(INDEX(Data!$AH$4:$AH$375,MATCH((WeekStart+3),Data!$A$4:$A$375,0)),""))/150),REPT("█",ROUND(MAX(0,MIN(1,(IFERROR(INDEX(Data!$AH$4:$AH$375,MATCH((WeekStart+3),Data!$A$4:$A$375,0)),""))/150))*6,0))&REPT("░",6-ROUND(MAX(0,MIN(1,(IFERROR(INDEX(Data!$AH$4:$AH$375,MATCH((WeekStart+3),Data!$A$4:$A$375,0)),""))/150))*6,0)),""),"") | L50: =IF(ISNUMBER(IFERROR(INDEX(Data!$AH$4:$AH$375,MATCH((WeekStart+3),Data!$A$4:$A$375,0)),"")),IFERROR(INDEX(Data!$AH$4:$AH$375,MATCH((WeekStart+3),Data!$A$4:$A$375,0)),""),"") | N50: ="Protein "&IF(ISNUMBER(IFERROR(INDEX(Data!$AH$4:$AH$375,MATCH((WeekStart+4),Data!$A$4:$A$375,0)),"")),IF(ISNUMBER((IFERROR(INDEX(Data!$AH$4:$AH$375,MATCH((WeekStart+4),Data!$A$4:$A$375,0)),""))/150),REPT("█",ROUND(MAX(0,MIN(1,(IFERROR(INDEX(Data!$AH$4:$AH$375,MATCH((WeekStart+4),Data!$A$4:$A$375,0)),""))/150))*6,0))&REPT("░",6-ROUND(MAX(0,MIN(1,(IFERROR(INDEX(Data!$AH$4:$AH$375,MATCH((WeekStart+4),Data!$A$4:$A$375,0)),""))/150))*6,0)),""),"") | O50: =IF(ISNUMBER(IFERROR(INDEX(Data!$AH$4:$AH$375,MATCH((WeekStart+4),Data!$A$4:$A$375,0)),"")),IFERROR(INDEX(Data!$AH$4:$AH$375,MATCH((WeekStart+4),Data!$A$4:$A$375,0)),""),"") | Q50: ="Protein "&IF(ISNUMBER(IFERROR(INDEX(Data!$AH$4:$AH$375,MATCH((WeekStart+5),Data!$A$4:$A$375,0)),"")),IF(ISNUMBER((IFERROR(INDEX(Data!$AH$4:$AH$375,MATCH((WeekStart+5),Data!$A$4:$A$375,0)),""))/150),REPT("█",ROUND(MAX(0,MIN(1,(IFERROR(INDEX(Data!$AH$4:$AH$375,MATCH((WeekStart+5),Data!$A$4:$A$375,0)),""))/150))*6,0))&REPT("░",6-ROUND(MAX(0,MIN(1,(IFERROR(INDEX(Data!$AH$4:$AH$375,MATCH((WeekStart+5),Data!$A$4:$A$375,0)),""))/150))*6,0)),""),"") | R50: =IF(ISNUMBER(IFERROR(INDEX(Data!$AH$4:$AH$375,MATCH((WeekStart+5),Data!$A$4:$A$375,0)),"")),IFERROR(INDEX(Data!$AH$4:$AH$375,MATCH((WeekStart+5),Data!$A$4:$A$375,0)),""),"") | T50: ="Protein "&IF(ISNUMBER(IFERROR(INDEX(Data!$AH$4:$AH$375,MATCH((WeekStart+6),Data!$A$4:$A$375,0)),"")),IF(ISNUMBER((IFERROR(INDEX(Data!$AH$4:$AH$375,MATCH((WeekStart+6),Data!$A$4:$A$375,0)),""))/150),REPT("█",ROUND(MAX(0,MIN(1,(IFERROR(INDEX(Data!$AH$4:$AH$375,MATCH((WeekStart+6),Data!$A$4:$A$375,0)),""))/150))*6,0))&REPT("░",6-ROUND(MAX(0,MIN(1,(IFERROR(INDEX(Data!$AH$4:$AH$375,MATCH((WeekStart+6),Data!$A$4:$A$375,0)),""))/150))*6,0)),""),"") | U50: =IF(ISNUMBER(IFERROR(INDEX(Data!$AH$4:$AH$375,MATCH((WeekStart+6),Data!$A$4:$A$375,0)),"")),IFERROR(INDEX(Data!$AH$4:$AH$375,MATCH((WeekStart+6),Data!$A$4:$A$375,0)),""),"")
B51: ="Steps "&IF(ISNUMBER(IFERROR(INDEX(Data!$AG$4:$AG$375,MATCH((WeekStart+0),Data!$A$4:$A$375,0)),"")),IF(ISNUMBER((IFERROR(INDEX(Data!$AG$4:$AG$375,MATCH((WeekStart+0),Data!$A$4:$A$375,0)),""))/10000),REPT("█",ROUND(MAX(0,MIN(1,(IFERROR(INDEX(Data!$AG$4:$AG$375,MATCH((WeekStart+0),Data!$A$4:$A$375,0)),""))/10000))*6,0))&REPT("░",6-ROUND(MAX(0,MIN(1,(IFERROR(INDEX(Data!$AG$4:$AG$375,MATCH((WeekStart+0),Data!$A$4:$A$375,0)),""))/10000))*6,0)),""),"") | C51: =IF(ISNUMBER(IFERROR(INDEX(Data!$AG$4:$AG$375,MATCH((WeekStart+0),Data!$A$4:$A$375,0)),"")),(IFERROR(INDEX(Data!$AG$4:$AG$375,MATCH((WeekStart+0),Data!$A$4:$A$375,0)),""))/1000,"") | E51: ="Steps "&IF(ISNUMBER(IFERROR(INDEX(Data!$AG$4:$AG$375,MATCH((WeekStart+1),Data!$A$4:$A$375,0)),"")),IF(ISNUMBER((IFERROR(INDEX(Data!$AG$4:$AG$375,MATCH((WeekStart+1),Data!$A$4:$A$375,0)),""))/10000),REPT("█",ROUND(MAX(0,MIN(1,(IFERROR(INDEX(Data!$AG$4:$AG$375,MATCH((WeekStart+1),Data!$A$4:$A$375,0)),""))/10000))*6,0))&REPT("░",6-ROUND(MAX(0,MIN(1,(IFERROR(INDEX(Data!$AG$4:$AG$375,MATCH((WeekStart+1),Data!$A$4:$A$375,0)),""))/10000))*6,0)),""),"") | F51: =IF(ISNUMBER(IFERROR(INDEX(Data!$AG$4:$AG$375,MATCH((WeekStart+1),Data!$A$4:$A$375,0)),"")),(IFERROR(INDEX(Data!$AG$4:$AG$375,MATCH((WeekStart+1),Data!$A$4:$A$375,0)),""))/1000,"") | H51: ="Steps "&IF(ISNUMBER(IFERROR(INDEX(Data!$AG$4:$AG$375,MATCH((WeekStart+2),Data!$A$4:$A$375,0)),"")),IF(ISNUMBER((IFERROR(INDEX(Data!$AG$4:$AG$375,MATCH((WeekStart+2),Data!$A$4:$A$375,0)),""))/10000),REPT("█",ROUND(MAX(0,MIN(1,(IFERROR(INDEX(Data!$AG$4:$AG$375,MATCH((WeekStart+2),Data!$A$4:$A$375,0)),""))/10000))*6,0))&REPT("░",6-ROUND(MAX(0,MIN(1,(IFERROR(INDEX(Data!$AG$4:$AG$375,MATCH((WeekStart+2),Data!$A$4:$A$375,0)),""))/10000))*6,0)),""),"") | I51: =IF(ISNUMBER(IFERROR(INDEX(Data!$AG$4:$AG$375,MATCH((WeekStart+2),Data!$A$4:$A$375,0)),"")),(IFERROR(INDEX(Data!$AG$4:$AG$375,MATCH((WeekStart+2),Data!$A$4:$A$375,0)),""))/1000,"") | K51: ="Steps "&IF(ISNUMBER(IFERROR(INDEX(Data!$AG$4:$AG$375,MATCH((WeekStart+3),Data!$A$4:$A$375,0)),"")),IF(ISNUMBER((IFERROR(INDEX(Data!$AG$4:$AG$375,MATCH((WeekStart+3),Data!$A$4:$A$375,0)),""))/10000),REPT("█",ROUND(MAX(0,MIN(1,(IFERROR(INDEX(Data!$AG$4:$AG$375,MATCH((WeekStart+3),Data!$A$4:$A$375,0)),""))/10000))*6,0))&REPT("░",6-ROUND(MAX(0,MIN(1,(IFERROR(INDEX(Data!$AG$4:$AG$375,MATCH((WeekStart+3),Data!$A$4:$A$375,0)),""))/10000))*6,0)),""),"") | L51: =IF(ISNUMBER(IFERROR(INDEX(Data!$AG$4:$AG$375,MATCH((WeekStart+3),Data!$A$4:$A$375,0)),"")),(IFERROR(INDEX(Data!$AG$4:$AG$375,MATCH((WeekStart+3),Data!$A$4:$A$375,0)),""))/1000,"") | N51: ="Steps "&IF(ISNUMBER(IFERROR(INDEX(Data!$AG$4:$AG$375,MATCH((WeekStart+4),Data!$A$4:$A$375,0)),"")),IF(ISNUMBER((IFERROR(INDEX(Data!$AG$4:$AG$375,MATCH((WeekStart+4),Data!$A$4:$A$375,0)),""))/10000),REPT("█",ROUND(MAX(0,MIN(1,(IFERROR(INDEX(Data!$AG$4:$AG$375,MATCH((WeekStart+4),Data!$A$4:$A$375,0)),""))/10000))*6,0))&REPT("░",6-ROUND(MAX(0,MIN(1,(IFERROR(INDEX(Data!$AG$4:$AG$375,MATCH((WeekStart+4),Data!$A$4:$A$375,0)),""))/10000))*6,0)),""),"") | O51: =IF(ISNUMBER(IFERROR(INDEX(Data!$AG$4:$AG$375,MATCH((WeekStart+4),Data!$A$4:$A$375,0)),"")),(IFERROR(INDEX(Data!$AG$4:$AG$375,MATCH((WeekStart+4),Data!$A$4:$A$375,0)),""))/1000,"") | Q51: ="Steps "&IF(ISNUMBER(IFERROR(INDEX(Data!$AG$4:$AG$375,MATCH((WeekStart+5),Data!$A$4:$A$375,0)),"")),IF(ISNUMBER((IFERROR(INDEX(Data!$AG$4:$AG$375,MATCH((WeekStart+5),Data!$A$4:$A$375,0)),""))/10000),REPT("█",ROUND(MAX(0,MIN(1,(IFERROR(INDEX(Data!$AG$4:$AG$375,MATCH((WeekStart+5),Data!$A$4:$A$375,0)),""))/10000))*6,0))&REPT("░",6-ROUND(MAX(0,MIN(1,(IFERROR(INDEX(Data!$AG$4:$AG$375,MATCH((WeekStart+5),Data!$A$4:$A$375,0)),""))/10000))*6,0)),""),"") | R51: =IF(ISNUMBER(IFERROR(INDEX(Data!$AG$4:$AG$375,MATCH((WeekStart+5),Data!$A$4:$A$375,0)),"")),(IFERROR(INDEX(Data!$AG$4:$AG$375,MATCH((WeekStart+5),Data!$A$4:$A$375,0)),""))/1000,"") | T51: ="Steps "&IF(ISNUMBER(IFERROR(INDEX(Data!$AG$4:$AG$375,MATCH((WeekStart+6),Data!$A$4:$A$375,0)),"")),IF(ISNUMBER((IFERROR(INDEX(Data!$AG$4:$AG$375,MATCH((WeekStart+6),Data!$A$4:$A$375,0)),""))/10000),REPT("█",ROUND(MAX(0,MIN(1,(IFERROR(INDEX(Data!$AG$4:$AG$375,MATCH((WeekStart+6),Data!$A$4:$A$375,0)),""))/10000))*6,0))&REPT("░",6-ROUND(MAX(0,MIN(1,(IFERROR(INDEX(Data!$AG$4:$AG$375,MATCH((WeekStart+6),Data!$A$4:$A$375,0)),""))/10000))*6,0)),""),"") | U51: =IF(ISNUMBER(IFERROR(INDEX(Data!$AG$4:$AG$375,MATCH((WeekStart+6),Data!$A$4:$A$375,0)),"")),(IFERROR(INDEX(Data!$AG$4:$AG$375,MATCH((WeekStart+6),Data!$A$4:$A$375,0)),""))/1000,"")
B55: chart data below (kept invisible on purpose)
B57: =TEXT((WeekStart+0),"ddd") | C57: =(WeekStart+0) | D57: =IFERROR(INDEX(Data!$BF$4:$BF$375,MATCH((WeekStart+0),Data!$A$4:$A$375,0)),"") | E57: =IF(ISNUMBER(D57),D57,NA()) | F57: =IF(ISNUMBER(D57),D57,0) | G57: =1-F57 | H57: =IF(ISNUMBER(IFERROR(INDEX(Data!$AL$4:$AL$375,MATCH((WeekStart+0),Data!$A$4:$A$375,0)),"")),IFERROR(INDEX(Data!$AL$4:$AL$375,MATCH((WeekStart+0),Data!$A$4:$A$375,0)),""),NA()) | I57: =IF(ISNUMBER(IFERROR(INDEX(Data!$AM$4:$AM$375,MATCH((WeekStart+0),Data!$A$4:$A$375,0)),"")),IFERROR(INDEX(Data!$AM$4:$AM$375,MATCH((WeekStart+0),Data!$A$4:$A$375,0)),""),NA()) | J57: =IF(ISNUMBER(IFERROR(INDEX(Data!$AN$4:$AN$375,MATCH((WeekStart+0),Data!$A$4:$A$375,0)),"")),IFERROR(INDEX(Data!$AN$4:$AN$375,MATCH((WeekStart+0),Data!$A$4:$A$375,0)),""),NA())
B58: =TEXT((WeekStart+1),"ddd") | C58: =(WeekStart+1) | D58: =IFERROR(INDEX(Data!$BF$4:$BF$375,MATCH((WeekStart+1),Data!$A$4:$A$375,0)),"") | E58: =IF(ISNUMBER(D58),D58,NA()) | F58: =IF(ISNUMBER(D58),D58,0) | G58: =1-F58 | H58: =IF(ISNUMBER(IFERROR(INDEX(Data!$AL$4:$AL$375,MATCH((WeekStart+1),Data!$A$4:$A$375,0)),"")),IFERROR(INDEX(Data!$AL$4:$AL$375,MATCH((WeekStart+1),Data!$A$4:$A$375,0)),""),NA()) | I58: =IF(ISNUMBER(IFERROR(INDEX(Data!$AM$4:$AM$375,MATCH((WeekStart+1),Data!$A$4:$A$375,0)),"")),IFERROR(INDEX(Data!$AM$4:$AM$375,MATCH((WeekStart+1),Data!$A$4:$A$375,0)),""),NA()) | J58: =IF(ISNUMBER(IFERROR(INDEX(Data!$AN$4:$AN$375,MATCH((WeekStart+1),Data!$A$4:$A$375,0)),"")),IFERROR(INDEX(Data!$AN$4:$AN$375,MATCH((WeekStart+1),Data!$A$4:$A$375,0)),""),NA())
B59: =TEXT((WeekStart+2),"ddd") | C59: =(WeekStart+2) | D59: =IFERROR(INDEX(Data!$BF$4:$BF$375,MATCH((WeekStart+2),Data!$A$4:$A$375,0)),"") | E59: =IF(ISNUMBER(D59),D59,NA()) | F59: =IF(ISNUMBER(D59),D59,0) | G59: =1-F59 | H59: =IF(ISNUMBER(IFERROR(INDEX(Data!$AL$4:$AL$375,MATCH((WeekStart+2),Data!$A$4:$A$375,0)),"")),IFERROR(INDEX(Data!$AL$4:$AL$375,MATCH((WeekStart+2),Data!$A$4:$A$375,0)),""),NA()) | I59: =IF(ISNUMBER(IFERROR(INDEX(Data!$AM$4:$AM$375,MATCH((WeekStart+2),Data!$A$4:$A$375,0)),"")),IFERROR(INDEX(Data!$AM$4:$AM$375,MATCH((WeekStart+2),Data!$A$4:$A$375,0)),""),NA()) | J59: =IF(ISNUMBER(IFERROR(INDEX(Data!$AN$4:$AN$375,MATCH((WeekStart+2),Data!$A$4:$A$375,0)),"")),IFERROR(INDEX(Data!$AN$4:$AN$375,MATCH((WeekStart+2),Data!$A$4:$A$375,0)),""),NA())
B60: =TEXT((WeekStart+3),"ddd") | C60: =(WeekStart+3) | D60: =IFERROR(INDEX(Data!$BF$4:$BF$375,MATCH((WeekStart+3),Data!$A$4:$A$375,0)),"") | E60: =IF(ISNUMBER(D60),D60,NA()) | F60: =IF(ISNUMBER(D60),D60,0) | G60: =1-F60 | H60: =IF(ISNUMBER(IFERROR(INDEX(Data!$AL$4:$AL$375,MATCH((WeekStart+3),Data!$A$4:$A$375,0)),"")),IFERROR(INDEX(Data!$AL$4:$AL$375,MATCH((WeekStart+3),Data!$A$4:$A$375,0)),""),NA()) | I60: =IF(ISNUMBER(IFERROR(INDEX(Data!$AM$4:$AM$375,MATCH((WeekStart+3),Data!$A$4:$A$375,0)),"")),IFERROR(INDEX(Data!$AM$4:$AM$375,MATCH((WeekStart+3),Data!$A$4:$A$375,0)),""),NA()) | J60: =IF(ISNUMBER(IFERROR(INDEX(Data!$AN$4:$AN$375,MATCH((WeekStart+3),Data!$A$4:$A$375,0)),"")),IFERROR(INDEX(Data!$AN$4:$AN$375,MATCH((WeekStart+3),Data!$A$4:$A$375,0)),""),NA())
B61: =TEXT((WeekStart+4),"ddd") | C61: =(WeekStart+4) | D61: =IFERROR(INDEX(Data!$BF$4:$BF$375,MATCH((WeekStart+4),Data!$A$4:$A$375,0)),"") | E61: =IF(ISNUMBER(D61),D61,NA()) | F61: =IF(ISNUMBER(D61),D61,0) | G61: =1-F61 | H61: =IF(ISNUMBER(IFERROR(INDEX(Data!$AL$4:$AL$375,MATCH((WeekStart+4),Data!$A$4:$A$375,0)),"")),IFERROR(INDEX(Data!$AL$4:$AL$375,MATCH((WeekStart+4),Data!$A$4:$A$375,0)),""),NA()) | I61: =IF(ISNUMBER(IFERROR(INDEX(Data!$AM$4:$AM$375,MATCH((WeekStart+4),Data!$A$4:$A$375,0)),"")),IFERROR(INDEX(Data!$AM$4:$AM$375,MATCH((WeekStart+4),Data!$A$4:$A$375,0)),""),NA()) | J61: =IF(ISNUMBER(IFERROR(INDEX(Data!$AN$4:$AN$375,MATCH((WeekStart+4),Data!$A$4:$A$375,0)),"")),IFERROR(INDEX(Data!$AN$4:$AN$375,MATCH((WeekStart+4),Data!$A$4:$A$375,0)),""),NA())
B62: =TEXT((WeekStart+5),"ddd") | C62: =(WeekStart+5) | D62: =IFERROR(INDEX(Data!$BF$4:$BF$375,MATCH((WeekStart+5),Data!$A$4:$A$375,0)),"") | E62: =IF(ISNUMBER(D62),D62,NA()) | F62: =IF(ISNUMBER(D62),D62,0) | G62: =1-F62 | H62: =IF(ISNUMBER(IFERROR(INDEX(Data!$AL$4:$AL$375,MATCH((WeekStart+5),Data!$A$4:$A$375,0)),"")),IFERROR(INDEX(Data!$AL$4:$AL$375,MATCH((WeekStart+5),Data!$A$4:$A$375,0)),""),NA()) | I62: =IF(ISNUMBER(IFERROR(INDEX(Data!$AM$4:$AM$375,MATCH((WeekStart+5),Data!$A$4:$A$375,0)),"")),IFERROR(INDEX(Data!$AM$4:$AM$375,MATCH((WeekStart+5),Data!$A$4:$A$375,0)),""),NA()) | J62: =IF(ISNUMBER(IFERROR(INDEX(Data!$AN$4:$AN$375,MATCH((WeekStart+5),Data!$A$4:$A$375,0)),"")),IFERROR(INDEX(Data!$AN$4:$AN$375,MATCH((WeekStart+5),Data!$A$4:$A$375,0)),""),NA())
B63: =TEXT((WeekStart+6),"ddd") | C63: =(WeekStart+6) | D63: =IFERROR(INDEX(Data!$BF$4:$BF$375,MATCH((WeekStart+6),Data!$A$4:$A$375,0)),"") | E63: =IF(ISNUMBER(D63),D63,NA()) | F63: =IF(ISNUMBER(D63),D63,0) | G63: =1-F63 | H63: =IF(ISNUMBER(IFERROR(INDEX(Data!$AL$4:$AL$375,MATCH((WeekStart+6),Data!$A$4:$A$375,0)),"")),IFERROR(INDEX(Data!$AL$4:$AL$375,MATCH((WeekStart+6),Data!$A$4:$A$375,0)),""),NA()) | I63: =IF(ISNUMBER(IFERROR(INDEX(Data!$AM$4:$AM$375,MATCH((WeekStart+6),Data!$A$4:$A$375,0)),"")),IFERROR(INDEX(Data!$AM$4:$AM$375,MATCH((WeekStart+6),Data!$A$4:$A$375,0)),""),NA()) | J63: =IF(ISNUMBER(IFERROR(INDEX(Data!$AN$4:$AN$375,MATCH((WeekStart+6),Data!$A$4:$A$375,0)),"")),IFERROR(INDEX(Data!$AN$4:$AN$375,MATCH((WeekStart+6),Data!$A$4:$A$375,0)),""),NA())
B64: week | D64: =IFERROR(AVERAGE(D57:D63),"") | F64: =IF(ISNUMBER(D64),D64,0) | G64: =1-F64

Sheet Oct 2026
AP1: =DATE(2026,10,1)
B2: =UPPER(TEXT($AP$1,"mmmm")) | E2: HABITS | L2: CHECK-INS | S2: FOUNDATION · MONTH | AC2: ROLLING 7-DAY | AK2: ROLLING 30-DAY | AP2: =ProtHit
B3: ="— Life OS · Habit Tracker · "&YEAR($AP$1)&" —" | E3: =COUNTA(B10:B18,B20:B32,B34:B37) | L3: =COUNTIF(E10:AI18,TRUE)+COUNTIF(E10:AI18,"x")+COUNTIF(E20:AI32,TRUE)+COUNTIF(E20:AI32,"x")+COUNTIF(E34:AI37,TRUE)+COUNTIF(E34:AI37,"x") | S3: =IF(ISNUMBER(AK39),TEXT(AK39,"0%")&" "&IF(ISNUMBER(AK39),REPT("█",ROUND(MAX(0,MIN(1,AK39))*12,0))&REPT("░",12-ROUND(MAX(0,MIN(1,AK39))*12,0)),""),"—") | AC3: =IF(ISNUMBER(IFERROR(INDEX(Data!$BG$4:$BG$375,MATCH($AP$13,Data!$A$4:$A$375,0)),"")),TEXT(IFERROR(INDEX(Data!$BG$4:$BG$375,MATCH($AP$13,Data!$A$4:$A$375,0)),""),"0%")&" · "&IF(NOT(ISNUMBER(IFERROR(INDEX(Data!$BG$4:$BG$375,MATCH($AP$13,Data!$A$4:$A$375,0)),""))),"—",IF(IFERROR(INDEX(Data!$BG$4:$BG$375,MATCH($AP$13,Data!$A$4:$A$375,0)),"")>=Band1,"GREEN",IF(IFERROR(INDEX(Data!$BG$4:$BG$375,MATCH($AP$13,Data!$A$4:$A$375,0)),"")>=Band2,"GOOD",IF(IFERROR(INDEX(Data!$BG$4:$BG$375,MATCH($AP$13,Data!$A$4:$A$375,0)),"")>=Band3,"NEEDS ATTENTION","RESET")))),"—") | AK3: =IF(ISNUMBER(IFERROR(INDEX(Data!$BH$4:$BH$375,MATCH($AP$13,Data!$A$4:$A$375,0)),"")),TEXT(IFERROR(INDEX(Data!$BH$4:$BH$375,MATCH($AP$13,Data!$A$4:$A$375,0)),""),"0%")&" · "&IF(NOT(ISNUMBER(IFERROR(INDEX(Data!$BH$4:$BH$375,MATCH($AP$13,Data!$A$4:$A$375,0)),""))),"—",IF(IFERROR(INDEX(Data!$BH$4:$BH$375,MATCH($AP$13,Data!$A$4:$A$375,0)),"")>=Band1,"GREEN",IF(IFERROR(INDEX(Data!$BH$4:$BH$375,MATCH($AP$13,Data!$A$4:$A$375,0)),"")>=Band2,"GOOD",IF(IFERROR(INDEX(Data!$BH$4:$BH$375,MATCH($AP$13,Data!$A$4:$A$375,0)),"")>=Band3,"NEEDS ATTENTION","RESET")))),"—") | AP3: =WaterHit
AP4: =SleepMin
B5: MY HABITS | E5: Week 1 | L5: Week 2 | S5: Week 3 | Z5: Week 4 | AG5: Week 5 | AK5: ANALYSIS | AP5: =SleepLow
B6: Tick what you did. Missed is data, not failure. | E6: =IF(E7="","",LEFT(TEXT(E7,"ddd"),2)) | F6: =IF(F7="","",LEFT(TEXT(F7,"ddd"),2)) | G6: =IF(G7="","",LEFT(TEXT(G7,"ddd"),2)) | H6: =IF(H7="","",LEFT(TEXT(H7,"ddd"),2)) | I6: =IF(I7="","",LEFT(TEXT(I7,"ddd"),2)) | J6: =IF(J7="","",LEFT(TEXT(J7,"ddd"),2)) | K6: =IF(K7="","",LEFT(TEXT(K7,"ddd"),2)) | L6: =IF(L7="","",LEFT(TEXT(L7,"ddd"),2)) | ... AI6: =IF(AI7="","",LEFT(TEXT(AI7,"ddd"),2)) | AK6: Done | AL6: Goal | AM6: Progress | AN6: % | AP6: =TODAY()
B7: Habit | C7: Pillar | D7: Target | E7: =IF(1<=DAY(EOMONTH($AP$1,0)),$AP$1+0,"") | F7: =IF(2<=DAY(EOMONTH($AP$1,0)),$AP$1+1,"") | G7: =IF(3<=DAY(EOMONTH($AP$1,0)),$AP$1+2,"") | H7: =IF(4<=DAY(EOMONTH($AP$1,0)),$AP$1+3,"") | I7: =IF(5<=DAY(EOMONTH($AP$1,0)),$AP$1+4,"") | J7: =IF(6<=DAY(EOMONTH($AP$1,0)),$AP$1+5,"") | K7: =IF(7<=DAY(EOMONTH($AP$1,0)),$AP$1+6,"") | L7: =IF(8<=DAY(EOMONTH($AP$1,0)),$AP$1+7,"") | M7: =IF(9<=DAY(EOMONTH($AP$1,0)),$AP$1+8,"") | N7: =IF(10<=DAY(EOMONTH($AP$1,0)),$AP$1+9,"") | O7: =IF(11<=DAY(EOMONTH($AP$1,0)),$AP$1+10,"") | P7: =IF(12<=DAY(EOMONTH($AP$1,0)),$AP$1+11,"") | Q7: =IF(13<=DAY(EOMONTH($AP$1,0)),$AP$1+12,"") | R7: =IF(14<=DAY(EOMONTH($AP$1,0)),$AP$1+13,"") | S7: =IF(15<=DAY(EOMONTH($AP$1,0)),$AP$1+14,"") | T7: =IF(16<=DAY(EOMONTH($AP$1,0)),$AP$1+15,"") | U7: =IF(17<=DAY(EOMONTH($AP$1,0)),$AP$1+16,"") | V7: =IF(18<=DAY(EOMONTH($AP$1,0)),$AP$1+17,"") | W7: =IF(19<=DAY(EOMONTH($AP$1,0)),$AP$1+18,"") | X7: =IF(20<=DAY(EOMONTH($AP$1,0)),$AP$1+19,"") | Y7: =IF(21<=DAY(EOMONTH($AP$1,0)),$AP$1+20,"") | Z7: =IF(22<=DAY(EOMONTH($AP$1,0)),$AP$1+21,"") | AA7: =IF(23<=DAY(EOMONTH($AP$1,0)),$AP$1+22,"") | AB7: =IF(24<=DAY(EOMONTH($AP$1,0)),$AP$1+23,"") | AC7: =IF(25<=DAY(EOMONTH($AP$1,0)),$AP$1+24,"") | AD7: =IF(26<=DAY(EOMONTH($AP$1,0)),$AP$1+25,"") | AE7: =IF(27<=DAY(EOMONTH($AP$1,0)),$AP$1+26,"") | AF7: =IF(28<=DAY(EOMONTH($AP$1,0)),$AP$1+27,"") | AG7: =IF(29<=DAY(EOMONTH($AP$1,0)),$AP$1+28,"") | AH7: =IF(30<=DAY(EOMONTH($AP$1,0)),$AP$1+29,"") | AI7: =IF(31<=DAY(EOMONTH($AP$1,0)),$AP$1+30,"") | AK7: goal = weekly target × days tracked | AP7: =KcalMin
B8: Day mode | C8: M = minimum · S = sick · R = rest | AK8: =COUNTIF(E8:AI8,"M")&" min · "&COUNTIF(E8:AI8,"S")&" sick · "&COUNTIF(E8:AI8,"R")&" rest" | AP8: =KcalMax
B9: LEVEL 1 · NON-NEGOTIABLES | AK9: the daily foundation | AP9: =COUNTIFS(Data!$B$4:$B$375,1,Data!$AO$4:$AO$375,1,Data!$E$4:$E$375,"<>S")
B10: 🌅 Morning reset | C10: HEALTH | D10: Daily | AK10: =COUNTIF(E10:AI10,TRUE)+COUNTIF(E10:AI10,"x") | AL10: =ROUND($AP$9*7/7,0) | AM10: =IF(ISNUMBER(AN10),REPT("█",ROUND(MAX(0,MIN(1,AN10))*10,0))&REPT("░",10-ROUND(MAX(0,MIN(1,AN10))*10,0)),"") | AN10: =IF(N(AL10)=0,"",MIN(1,AK10/AL10)) | AP10: =COUNTIFS(Data!$B$4:$B$375,1,Data!$AO$4:$AO$375,1,Data!$E$4:$E$375,"<>S",Data!$AS$4:$AS$375,1)
B11: 🙏 Prayer + Scripture ◆ | C11: SPIRIT | D11: Daily | AK11: =COUNTIF(E11:AI11,TRUE)+COUNTIF(E11:AI11,"x") | AL11: =ROUND($AP$9*7/7,0) | AM11: =IF(ISNUMBER(AN11),REPT("█",ROUND(MAX(0,MIN(1,AN11))*10,0))&REPT("░",10-ROUND(MAX(0,MIN(1,AN11))*10,0)),"") | AN11: =IF(N(AL11)=0,"",MIN(1,AK11/AL11)) | AP11: =_xlfn.MAXIFS(Data!$A$4:$A$375,Data!$B$4:$B$375,1,Data!$AF$4:$AF$375,">0")
B12: 🧘 Mobility & posture ◆ | C12: POSTURE | D12: Daily | AK12: =COUNTIF(E12:AI12,TRUE)+COUNTIF(E12:AI12,"x") | AL12: =ROUND($AP$9*7/7,0) | AM12: =IF(ISNUMBER(AN12),REPT("█",ROUND(MAX(0,MIN(1,AN12))*10,0))&REPT("░",10-ROUND(MAX(0,MIN(1,AN12))*10,0)),"") | AN12: =IF(N(AL12)=0,"",MIN(1,AK12/AL12)) | AP12: =_xlfn.MINIFS(Data!$A$4:$A$375,Data!$B$4:$B$375,1,Data!$AF$4:$AF$375,">0")
B13: 💪 Training / movement ◆ | C13: BODY | D13: Daily | AK13: =COUNTIF(E13:AI13,TRUE)+COUNTIF(E13:AI13,"x") | AL13: =ROUND($AP$9*7/7,0) | AM13: =IF(ISNUMBER(AN13),REPT("█",ROUND(MAX(0,MIN(1,AN13))*10,0))&REPT("░",10-ROUND(MAX(0,MIN(1,AN13))*10,0)),"") | AN13: =IF(N(AL13)=0,"",MIN(1,AK13/AL13)) | AP13: =MIN(AP6,EOMONTH(AP1,0))
B14: 🎯 Top 3 priorities | C14: WORK | D14: 5× / wk | AK14: =COUNTIF(E14:AI14,TRUE)+COUNTIF(E14:AI14,"x") | AL14: =$AP$10 | AM14: =IF(ISNUMBER(AN14),REPT("█",ROUND(MAX(0,MIN(1,AN14))*10,0))&REPT("░",10-ROUND(MAX(0,MIN(1,AN14))*10,0)),"") | AN14: =IF(N(AL14)=0,"",MIN(1,AK14/AL14))
B15: ❤️ Fiancée time ◆ | C15: RELATIONSHIPS | D15: Daily | AK15: =COUNTIF(E15:AI15,TRUE)+COUNTIF(E15:AI15,"x") | AL15: =ROUND($AP$9*7/7,0) | AM15: =IF(ISNUMBER(AN15),REPT("█",ROUND(MAX(0,MIN(1,AN15))*10,0))&REPT("░",10-ROUND(MAX(0,MIN(1,AN15))*10,0)),"") | AN15: =IF(N(AL15)=0,"",MIN(1,AK15/AL15))
B16: 📖 Read / learn | C16: MIND | D16: Daily | AK16: =COUNTIF(E16:AI16,TRUE)+COUNTIF(E16:AI16,"x") | AL16: =ROUND($AP$9*7/7,0) | AM16: =IF(ISNUMBER(AN16),REPT("█",ROUND(MAX(0,MIN(1,AN16))*10,0))&REPT("░",10-ROUND(MAX(0,MIN(1,AN16))*10,0)),"") | AN16: =IF(N(AL16)=0,"",MIN(1,AK16/AL16))
B17: 🌙 Evening shutdown | C17: WORK | D17: Daily | AK17: =COUNTIF(E17:AI17,TRUE)+COUNTIF(E17:AI17,"x") | AL17: =ROUND($AP$9*7/7,0) | AM17: =IF(ISNUMBER(AN17),REPT("█",ROUND(MAX(0,MIN(1,AN17))*10,0))&REPT("░",10-ROUND(MAX(0,MIN(1,AN17))*10,0)),"") | AN17: =IF(N(AL17)=0,"",MIN(1,AK17/AL17))
B18: 😴 Lights out 22:00 ◆ | C18: HEALTH | D18: Daily | AK18: =COUNTIF(E18:AI18,TRUE)+COUNTIF(E18:AI18,"x") | AL18: =ROUND($AP$9*7/7,0) | AM18: =IF(ISNUMBER(AN18),REPT("█",ROUND(MAX(0,MIN(1,AN18))*10,0))&REPT("░",10-ROUND(MAX(0,MIN(1,AN18))*10,0)),"") | AN18: =IF(N(AL18)=0,"",MIN(1,AK18/AL18))
B19: LEVEL 2 · HIGH VALUE | AK19: weekly targets
B20: 🏋️ Strength session | C20: BODY | D20: 4× / wk | AK20: =COUNTIF(E20:AI20,TRUE)+COUNTIF(E20:AI20,"x") | AL20: =ROUND($AP$9*4/7,0) | AM20: =IF(ISNUMBER(AN20),REPT("█",ROUND(MAX(0,MIN(1,AN20))*10,0))&REPT("░",10-ROUND(MAX(0,MIN(1,AN20))*10,0)),"") | AN20: =IF(N(AL20)=0,"",MIN(1,AK20/AL20))
B21: 📈 Progression achieved | C21: BODY | D21: 4× / wk | AK21: =COUNTIF(E21:AI21,TRUE)+COUNTIF(E21:AI21,"x") | AL21: =ROUND($AP$9*4/7,0) | AM21: =IF(ISNUMBER(AN21),REPT("█",ROUND(MAX(0,MIN(1,AN21))*10,0))&REPT("░",10-ROUND(MAX(0,MIN(1,AN21))*10,0)),"") | AN21: =IF(N(AL21)=0,"",MIN(1,AK21/AL21))
B22: 🧱 Core | C22: BODY | D22: 3× / wk | AK22: =COUNTIF(E22:AI22,TRUE)+COUNTIF(E22:AI22,"x") | AL22: =ROUND($AP$9*3/7,0) | AM22: =IF(ISNUMBER(AN22),REPT("█",ROUND(MAX(0,MIN(1,AN22))*10,0))&REPT("░",10-ROUND(MAX(0,MIN(1,AN22))*10,0)),"") | AN22: =IF(N(AL22)=0,"",MIN(1,AK22/AL22))
B23: 🦵 Calves | C23: BODY | D23: 3× / wk | AK23: =COUNTIF(E23:AI23,TRUE)+COUNTIF(E23:AI23,"x") | AL23: =ROUND($AP$9*3/7,0) | AM23: =IF(ISNUMBER(AN23),REPT("█",ROUND(MAX(0,MIN(1,AN23))*10,0))&REPT("░",10-ROUND(MAX(0,MIN(1,AN23))*10,0)),"") | AN23: =IF(N(AL23)=0,"",MIN(1,AK23/AL23))
B24: 🚶 Cardio | C24: BODY | D24: 2× / wk | AK24: =COUNTIF(E24:AI24,TRUE)+COUNTIF(E24:AI24,"x") | AL24: =ROUND($AP$9*2/7,0) | AM24: =IF(ISNUMBER(AN24),REPT("█",ROUND(MAX(0,MIN(1,AN24))*10,0))&REPT("░",10-ROUND(MAX(0,MIN(1,AN24))*10,0)),"") | AN24: =IF(N(AL24)=0,"",MIN(1,AK24/AL24))
B25: 🧠 Deep work 2+ blocks | C25: WORK | D25: 5× / wk | AK25: =COUNTIF(E25:AI25,TRUE)+COUNTIF(E25:AI25,"x") | AL25: =ROUND($AP$9*5/7,0) | AM25: =IF(ISNUMBER(AN25),REPT("█",ROUND(MAX(0,MIN(1,AN25))*10,0))&REPT("░",10-ROUND(MAX(0,MIN(1,AN25))*10,0)),"") | AN25: =IF(N(AL25)=0,"",MIN(1,AK25/AL25))
